2024-02-23 11:46:45 - INFO - =================== New Run Started: 2024-02-23 11:46:45 ===================
2024-02-23 11:46:45 - INFO - Tarning X_Reporto Started
2024-02-23 11:46:45 - INFO - MODEL_STAGE: 1
2024-02-23 11:46:45 - INFO - DEVICE: cuda
2024-02-23 11:46:45 - INFO - CONTINUE_TRAIN: False
2024-02-23 11:46:45 - INFO - TRAIN_RPN: True
2024-02-23 11:46:45 - INFO - RUN: 0
2024-02-23 11:46:45 - INFO - EPOCHS: 5
2024-02-23 11:46:45 - INFO - BATCH_SIZE: 32
2024-02-23 11:46:45 - INFO - LM_Batch_Size: 1
2024-02-23 11:46:45 - INFO - LEARNING_RATE: 0.0001
2024-02-23 11:46:45 - INFO - SCHEDULAR_STEP_SIZE: 1500
2024-02-23 11:46:45 - INFO - SCHEDULAR_GAMMA: 0.9
2024-02-23 11:46:45 - INFO - DEBUG: True
2024-02-23 11:46:45 - INFO - GENERATE_REPORT: False
2024-02-23 11:46:45 - INFO - ABNORMAL_CLASSIFIER_POS_WEIGHT: 6.0
2024-02-23 11:46:45 - INFO - REGION_SELECTION_CLASSIFIER_POS_WEIGHT: 2.24
2024-02-23 11:46:45 - INFO - training_csv_path: datasets/train.csv
2024-02-23 11:46:45 - INFO - validation_csv_path: datasets/train.csv
2024-02-23 11:46:45 - INFO - PERIODIC_LOGGING: False
2024-02-23 11:46:45 - INFO - Folder 'models/0' already exists.
2024-02-23 11:47:21 - INFO - =================== New Run Started: 2024-02-23 11:47:21 ===================
2024-02-23 11:47:21 - INFO - Tarning X_Reporto Started
2024-02-23 11:47:21 - INFO - MODEL_STAGE: 1
2024-02-23 11:47:21 - INFO - DEVICE: cuda
2024-02-23 11:47:21 - INFO - CONTINUE_TRAIN: False
2024-02-23 11:47:21 - INFO - TRAIN_RPN: True
2024-02-23 11:47:21 - INFO - RUN: 0
2024-02-23 11:47:21 - INFO - EPOCHS: 5
2024-02-23 11:47:21 - INFO - BATCH_SIZE: 32
2024-02-23 11:47:21 - INFO - LM_Batch_Size: 1
2024-02-23 11:47:21 - INFO - LEARNING_RATE: 0.0001
2024-02-23 11:47:21 - INFO - SCHEDULAR_STEP_SIZE: 1500
2024-02-23 11:47:21 - INFO - SCHEDULAR_GAMMA: 0.9
2024-02-23 11:47:21 - INFO - DEBUG: True
2024-02-23 11:47:21 - INFO - GENERATE_REPORT: False
2024-02-23 11:47:21 - INFO - ABNORMAL_CLASSIFIER_POS_WEIGHT: 6.0
2024-02-23 11:47:21 - INFO - REGION_SELECTION_CLASSIFIER_POS_WEIGHT: 2.24
2024-02-23 11:47:21 - INFO - training_csv_path: datasets/train.csv
2024-02-23 11:47:21 - INFO - validation_csv_path: datasets/train.csv
2024-02-23 11:47:21 - INFO - PERIODIC_LOGGING: False
2024-02-23 11:47:21 - INFO - Folder 'models/0' already exists.
2024-02-23 11:47:28 - DEBUG - Starting new HTTPS connection (1): huggingface.co:443
2024-02-23 11:47:29 - DEBUG - https://huggingface.co:443 "HEAD /healx/gpt-2-pubmed-medium/resolve/main/tokenizer_config.json HTTP/1.1" 200 0
2024-02-23 11:47:29 - DEBUG - Attempting to acquire lock 2256455263296 on C:\Users\Dell\.cache\huggingface\hub\.locks\models--healx--gpt-2-pubmed-medium\be4d21d94f3b4687e5a54d84bf6ab46ed0f8defd.lock
2024-02-23 11:47:29 - DEBUG - Lock 2256455263296 acquired on C:\Users\Dell\.cache\huggingface\hub\.locks\models--healx--gpt-2-pubmed-medium\be4d21d94f3b4687e5a54d84bf6ab46ed0f8defd.lock
2024-02-23 11:47:30 - DEBUG - https://huggingface.co:443 "GET /healx/gpt-2-pubmed-medium/resolve/main/tokenizer_config.json HTTP/1.1" 200 26
2024-02-23 11:47:30 - DEBUG - Attempting to release lock 2256455263296 on C:\Users\Dell\.cache\huggingface\hub\.locks\models--healx--gpt-2-pubmed-medium\be4d21d94f3b4687e5a54d84bf6ab46ed0f8defd.lock
2024-02-23 11:47:30 - DEBUG - Lock 2256455263296 released on C:\Users\Dell\.cache\huggingface\hub\.locks\models--healx--gpt-2-pubmed-medium\be4d21d94f3b4687e5a54d84bf6ab46ed0f8defd.lock
2024-02-23 11:47:30 - DEBUG - https://huggingface.co:443 "HEAD /healx/gpt-2-pubmed-medium/resolve/main/vocab.json HTTP/1.1" 200 0
2024-02-23 11:47:30 - DEBUG - Attempting to acquire lock 2256455262432 on C:\Users\Dell\.cache\huggingface\hub\.locks\models--healx--gpt-2-pubmed-medium\b00361fece0387ca34b4b8b8539ed830d644dbeb.lock
2024-02-23 11:47:30 - DEBUG - Lock 2256455262432 acquired on C:\Users\Dell\.cache\huggingface\hub\.locks\models--healx--gpt-2-pubmed-medium\b00361fece0387ca34b4b8b8539ed830d644dbeb.lock
2024-02-23 11:47:31 - DEBUG - https://huggingface.co:443 "GET /healx/gpt-2-pubmed-medium/resolve/main/vocab.json HTTP/1.1" 200 898669
2024-02-23 11:47:35 - DEBUG - Attempting to release lock 2256455262432 on C:\Users\Dell\.cache\huggingface\hub\.locks\models--healx--gpt-2-pubmed-medium\b00361fece0387ca34b4b8b8539ed830d644dbeb.lock
2024-02-23 11:47:35 - DEBUG - Lock 2256455262432 released on C:\Users\Dell\.cache\huggingface\hub\.locks\models--healx--gpt-2-pubmed-medium\b00361fece0387ca34b4b8b8539ed830d644dbeb.lock
2024-02-23 11:47:35 - DEBUG - https://huggingface.co:443 "HEAD /healx/gpt-2-pubmed-medium/resolve/main/merges.txt HTTP/1.1" 200 0
2024-02-23 11:47:35 - DEBUG - Attempting to acquire lock 2256455262816 on C:\Users\Dell\.cache\huggingface\hub\.locks\models--healx--gpt-2-pubmed-medium\226b0752cac7789c48f0cb3ec53eda48b7be36cc.lock
2024-02-23 11:47:35 - DEBUG - Lock 2256455262816 acquired on C:\Users\Dell\.cache\huggingface\hub\.locks\models--healx--gpt-2-pubmed-medium\226b0752cac7789c48f0cb3ec53eda48b7be36cc.lock
2024-02-23 11:47:36 - DEBUG - https://huggingface.co:443 "GET /healx/gpt-2-pubmed-medium/resolve/main/merges.txt HTTP/1.1" 200 456318
2024-02-23 11:47:38 - DEBUG - Attempting to release lock 2256455262816 on C:\Users\Dell\.cache\huggingface\hub\.locks\models--healx--gpt-2-pubmed-medium\226b0752cac7789c48f0cb3ec53eda48b7be36cc.lock
2024-02-23 11:47:38 - DEBUG - Lock 2256455262816 released on C:\Users\Dell\.cache\huggingface\hub\.locks\models--healx--gpt-2-pubmed-medium\226b0752cac7789c48f0cb3ec53eda48b7be36cc.lock
2024-02-23 11:47:38 - DEBUG - https://huggingface.co:443 "HEAD /healx/gpt-2-pubmed-medium/resolve/main/added_tokens.json HTTP/1.1" 404 0
2024-02-23 11:47:38 - DEBUG - https://huggingface.co:443 "HEAD /healx/gpt-2-pubmed-medium/resolve/main/special_tokens_map.json HTTP/1.1" 200 0
2024-02-23 11:47:38 - DEBUG - Attempting to acquire lock 2256455262048 on C:\Users\Dell\.cache\huggingface\hub\.locks\models--healx--gpt-2-pubmed-medium\817762d631ad6f9c799f6b9dc713c46420e65546.lock
2024-02-23 11:47:38 - DEBUG - Lock 2256455262048 acquired on C:\Users\Dell\.cache\huggingface\hub\.locks\models--healx--gpt-2-pubmed-medium\817762d631ad6f9c799f6b9dc713c46420e65546.lock
2024-02-23 11:47:39 - DEBUG - https://huggingface.co:443 "GET /healx/gpt-2-pubmed-medium/resolve/main/special_tokens_map.json HTTP/1.1" 200 90
2024-02-23 11:47:39 - DEBUG - Attempting to release lock 2256455262048 on C:\Users\Dell\.cache\huggingface\hub\.locks\models--healx--gpt-2-pubmed-medium\817762d631ad6f9c799f6b9dc713c46420e65546.lock
2024-02-23 11:47:39 - DEBUG - Lock 2256455262048 released on C:\Users\Dell\.cache\huggingface\hub\.locks\models--healx--gpt-2-pubmed-medium\817762d631ad6f9c799f6b9dc713c46420e65546.lock
2024-02-23 11:47:39 - DEBUG - https://huggingface.co:443 "HEAD /healx/gpt-2-pubmed-medium/resolve/main/tokenizer.json HTTP/1.1" 404 0
2024-02-23 11:47:39 - DEBUG - https://huggingface.co:443 "HEAD /healx/gpt-2-pubmed-medium/resolve/main/config.json HTTP/1.1" 200 0
2024-02-23 11:47:39 - DEBUG - Attempting to acquire lock 2256455262816 on C:\Users\Dell\.cache\huggingface\hub\.locks\models--healx--gpt-2-pubmed-medium\820cf16cc8c4c6ef3b0b8740e68622fb8bcf4723.lock
2024-02-23 11:47:39 - DEBUG - Lock 2256455262816 acquired on C:\Users\Dell\.cache\huggingface\hub\.locks\models--healx--gpt-2-pubmed-medium\820cf16cc8c4c6ef3b0b8740e68622fb8bcf4723.lock
2024-02-23 11:47:39 - DEBUG - https://huggingface.co:443 "GET /healx/gpt-2-pubmed-medium/resolve/main/config.json HTTP/1.1" 200 651
2024-02-23 11:47:39 - DEBUG - Attempting to release lock 2256455262816 on C:\Users\Dell\.cache\huggingface\hub\.locks\models--healx--gpt-2-pubmed-medium\820cf16cc8c4c6ef3b0b8740e68622fb8bcf4723.lock
2024-02-23 11:47:39 - DEBUG - Lock 2256455262816 released on C:\Users\Dell\.cache\huggingface\hub\.locks\models--healx--gpt-2-pubmed-medium\820cf16cc8c4c6ef3b0b8740e68622fb8bcf4723.lock
2024-02-23 11:47:39 - ERROR - An error occurred
Traceback (most recent call last):
  File "D:\Graduation-Project\src\x_reporto\trainer\x_reporto_trainer.py", line 836, in <module>
    main()
  File "D:\Graduation-Project\src\x_reporto\trainer\x_reporto_trainer.py", line 820, in main
    trainer = XReportoTrainer(model=x_reporto_model)
  File "D:\Graduation-Project\src\x_reporto\trainer\x_reporto_trainer.py", line 102, in __init__
    self.dataset_train = CustomDataset(dataset_path= training_csv_path, transform_type='train',tokenizer=self.tokenizer)
  File "D:\Graduation-Project\src\x_reporto\data_loader\custom_dataset.py", line 24, in __init__
    self.transform = CustomAugmentation(transform_type=self.transform_type)
  File "D:\Graduation-Project\src\object_detector\data_loader\custom_augmentation.py", line 29, in __init__
    self.transform=TransformLibrary(transform_type)
  File "D:\Graduation-Project\src\object_detector\data_loader\custom_augmentation.py", line 53, in __init__
    A.Affine(mode=cv2.BORDER_CONSTANT, cval=0, rotate=(-ANGLE, ANGLE),keep_ratio=True),
TypeError: Affine.__init__() got an unexpected keyword argument 'keep_ratio'
2024-02-23 11:48:55 - INFO - =================== New Run Started: 2024-02-23 11:48:55 ===================
2024-02-23 11:48:55 - INFO - Tarning X_Reporto Started
2024-02-23 11:48:55 - INFO - MODEL_STAGE: 1
2024-02-23 11:48:55 - INFO - DEVICE: cuda
2024-02-23 11:48:55 - INFO - CONTINUE_TRAIN: False
2024-02-23 11:48:55 - INFO - TRAIN_RPN: True
2024-02-23 11:48:55 - INFO - RUN: 0
2024-02-23 11:48:55 - INFO - EPOCHS: 5
2024-02-23 11:48:55 - INFO - BATCH_SIZE: 32
2024-02-23 11:48:55 - INFO - LM_Batch_Size: 1
2024-02-23 11:48:55 - INFO - LEARNING_RATE: 0.0001
2024-02-23 11:48:55 - INFO - SCHEDULAR_STEP_SIZE: 1500
2024-02-23 11:48:55 - INFO - SCHEDULAR_GAMMA: 0.9
2024-02-23 11:48:55 - INFO - DEBUG: True
2024-02-23 11:48:55 - INFO - GENERATE_REPORT: False
2024-02-23 11:48:55 - INFO - ABNORMAL_CLASSIFIER_POS_WEIGHT: 6.0
2024-02-23 11:48:55 - INFO - REGION_SELECTION_CLASSIFIER_POS_WEIGHT: 2.24
2024-02-23 11:48:55 - INFO - training_csv_path: datasets/train.csv
2024-02-23 11:48:55 - INFO - validation_csv_path: datasets/train.csv
2024-02-23 11:48:55 - INFO - PERIODIC_LOGGING: False
2024-02-23 11:48:55 - INFO - Folder 'models/0' already exists.
2024-02-23 11:49:01 - DEBUG - Starting new HTTPS connection (1): huggingface.co:443
2024-02-23 11:49:01 - DEBUG - https://huggingface.co:443 "HEAD /healx/gpt-2-pubmed-medium/resolve/main/tokenizer_config.json HTTP/1.1" 200 0
2024-02-23 11:49:01 - ERROR - An error occurred
Traceback (most recent call last):
  File "D:\Graduation-Project\src\x_reporto\trainer\x_reporto_trainer.py", line 836, in <module>
    main()
  File "D:\Graduation-Project\src\x_reporto\trainer\x_reporto_trainer.py", line 820, in main
    trainer = XReportoTrainer(model=x_reporto_model)
  File "D:\Graduation-Project\src\x_reporto\trainer\x_reporto_trainer.py", line 102, in __init__
    self.dataset_train = CustomDataset(dataset_path= training_csv_path, transform_type='train',tokenizer=self.tokenizer)
  File "D:\Graduation-Project\src\x_reporto\data_loader\custom_dataset.py", line 24, in __init__
    self.transform = CustomAugmentation(transform_type=self.transform_type)
  File "D:\Graduation-Project\src\object_detector\data_loader\custom_augmentation.py", line 29, in __init__
    self.transform=TransformLibrary(transform_type)
  File "D:\Graduation-Project\src\object_detector\data_loader\custom_augmentation.py", line 53, in __init__
    A.Affine(mode=cv2.BORDER_CONSTANT, cval=0, rotate=(-ANGLE, ANGLE),keep_ratio=True),
TypeError: Affine.__init__() got an unexpected keyword argument 'keep_ratio'
2024-02-23 14:03:20 - INFO - =================== New Run Started: 2024-02-23 14:03:20 ===================
2024-02-23 14:03:20 - INFO - Tarning X_Reporto Started
2024-02-23 14:03:20 - INFO - MODEL_STAGE: 1
2024-02-23 14:03:20 - INFO - DEVICE: cuda
2024-02-23 14:03:20 - INFO - CONTINUE_TRAIN: False
2024-02-23 14:03:20 - INFO - TRAIN_RPN: True
2024-02-23 14:03:20 - INFO - RUN: 0
2024-02-23 14:03:20 - INFO - EPOCHS: 5
2024-02-23 14:03:20 - INFO - BATCH_SIZE: 32
2024-02-23 14:03:20 - INFO - LM_Batch_Size: 1
2024-02-23 14:03:20 - INFO - LEARNING_RATE: 0.0001
2024-02-23 14:03:20 - INFO - SCHEDULAR_STEP_SIZE: 1500
2024-02-23 14:03:20 - INFO - SCHEDULAR_GAMMA: 0.9
2024-02-23 14:03:20 - INFO - DEBUG: True
2024-02-23 14:03:20 - INFO - GENERATE_REPORT: False
2024-02-23 14:03:20 - INFO - ABNORMAL_CLASSIFIER_POS_WEIGHT: 6.0
2024-02-23 14:03:20 - INFO - REGION_SELECTION_CLASSIFIER_POS_WEIGHT: 2.24
2024-02-23 14:03:20 - INFO - training_csv_path: datasets/train.csv
2024-02-23 14:03:20 - INFO - validation_csv_path: datasets/train.csv
2024-02-23 14:03:20 - INFO - PERIODIC_LOGGING: False
2024-02-23 14:03:20 - INFO - Folder 'models/0' already exists.
2024-02-23 14:03:24 - DEBUG - Starting new HTTPS connection (1): huggingface.co:443
2024-02-23 14:03:24 - DEBUG - https://huggingface.co:443 "HEAD /healx/gpt-2-pubmed-medium/resolve/main/tokenizer_config.json HTTP/1.1" 200 0
2024-02-23 14:04:38 - INFO - =================== New Run Started: 2024-02-23 14:04:38 ===================
2024-02-23 14:04:38 - INFO - Tarning X_Reporto Started
2024-02-23 14:04:38 - INFO - MODEL_STAGE: 1
2024-02-23 14:04:38 - INFO - DEVICE: cuda
2024-02-23 14:04:38 - INFO - CONTINUE_TRAIN: False
2024-02-23 14:04:38 - INFO - TRAIN_RPN: True
2024-02-23 14:04:38 - INFO - RUN: 0
2024-02-23 14:04:38 - INFO - EPOCHS: 5
2024-02-23 14:04:38 - INFO - BATCH_SIZE: 1
2024-02-23 14:04:38 - INFO - LM_Batch_Size: 1
2024-02-23 14:04:38 - INFO - LEARNING_RATE: 0.0001
2024-02-23 14:04:38 - INFO - SCHEDULAR_STEP_SIZE: 1500
2024-02-23 14:04:38 - INFO - SCHEDULAR_GAMMA: 0.9
2024-02-23 14:04:38 - INFO - DEBUG: True
2024-02-23 14:04:38 - INFO - GENERATE_REPORT: False
2024-02-23 14:04:38 - INFO - ABNORMAL_CLASSIFIER_POS_WEIGHT: 6.0
2024-02-23 14:04:38 - INFO - REGION_SELECTION_CLASSIFIER_POS_WEIGHT: 2.24
2024-02-23 14:04:38 - INFO - training_csv_path: datasets/train.csv
2024-02-23 14:04:38 - INFO - validation_csv_path: datasets/train.csv
2024-02-23 14:04:38 - INFO - PERIODIC_LOGGING: False
2024-02-23 14:04:38 - INFO - Folder 'models/0' already exists.
2024-02-23 14:04:41 - DEBUG - Starting new HTTPS connection (1): huggingface.co:443
2024-02-23 14:04:42 - DEBUG - https://huggingface.co:443 "HEAD /healx/gpt-2-pubmed-medium/resolve/main/tokenizer_config.json HTTP/1.1" 200 0
2024-02-23 14:51:25 - INFO - =================== New Run Started: 2024-02-23 14:51:25 ===================
2024-02-23 14:51:25 - INFO - Tarning X_Reporto Started
2024-02-23 14:51:25 - INFO - MODEL_STAGE: 3
2024-02-23 14:51:25 - INFO - DEVICE: cuda
2024-02-23 14:51:25 - INFO - CONTINUE_TRAIN: False
2024-02-23 14:51:25 - INFO - TRAIN_RPN: True
2024-02-23 14:51:25 - INFO - RUN: 0
2024-02-23 14:51:25 - INFO - EPOCHS: 5
2024-02-23 14:51:25 - INFO - BATCH_SIZE: 4
2024-02-23 14:51:25 - INFO - LM_Batch_Size: 1
2024-02-23 14:51:25 - INFO - LEARNING_RATE: 0.0001
2024-02-23 14:51:25 - INFO - SCHEDULAR_STEP_SIZE: 1500
2024-02-23 14:51:25 - INFO - SCHEDULAR_GAMMA: 0.9
2024-02-23 14:51:25 - INFO - DEBUG: True
2024-02-23 14:51:25 - INFO - GENERATE_REPORT: False
2024-02-23 14:51:25 - INFO - ABNORMAL_CLASSIFIER_POS_WEIGHT: 6.0
2024-02-23 14:51:25 - INFO - REGION_SELECTION_CLASSIFIER_POS_WEIGHT: 2.24
2024-02-23 14:51:25 - INFO - training_csv_path: datasets/train.csv
2024-02-23 14:51:25 - INFO - validation_csv_path: datasets/train.csv
2024-02-23 14:51:25 - INFO - PERIODIC_LOGGING: False
2024-02-23 14:51:25 - INFO - Folder 'models/0' already exists.
2024-02-23 14:51:30 - DEBUG - Starting new HTTPS connection (1): huggingface.co:443
2024-02-23 14:51:31 - DEBUG - https://huggingface.co:443 "HEAD /gpt2/resolve/main/config.json HTTP/1.1" 200 0
2024-02-23 14:51:31 - DEBUG - https://huggingface.co:443 "HEAD /gpt2/resolve/main/config.json HTTP/1.1" 200 0
2024-02-23 14:51:32 - DEBUG - https://huggingface.co:443 "HEAD /gpt2/resolve/main/generation_config.json HTTP/1.1" 200 0
2024-02-23 14:51:34 - DEBUG - https://huggingface.co:443 "HEAD /healx/gpt-2-pubmed-medium/resolve/main/tokenizer_config.json HTTP/1.1" 200 0
2024-02-23 14:51:44 - ERROR - An error occurred
Traceback (most recent call last):
  File "D:\Engineering\Fourth_Year\First_Term\Graduation\Graduation-Project\src\x_reporto\trainer\x_reporto_trainer.py", line 817, in <module>
    main()
  File "D:\Engineering\Fourth_Year\First_Term\Graduation\Graduation-Project\src\x_reporto\trainer\x_reporto_trainer.py", line 805, in main
    trainer.train()
  File "D:\Engineering\Fourth_Year\First_Term\Graduation\Graduation-Project\src\x_reporto\trainer\x_reporto_trainer.py", line 125, in train
    for batch_idx,(images,object_detector_targets,selection_classifier_targets,abnormal_classifier_targets,LM_inputs,LM_targets) in enumerate(self.data_loader_train):
  File "D:\anaconda3\envs\pt\Lib\site-packages\torch\utils\data\dataloader.py", line 631, in __next__
    data = self._next_data()
           ^^^^^^^^^^^^^^^^^
  File "D:\anaconda3\envs\pt\Lib\site-packages\torch\utils\data\dataloader.py", line 1346, in _next_data
    return self._process_data(data)
           ^^^^^^^^^^^^^^^^^^^^^^^^
  File "D:\anaconda3\envs\pt\Lib\site-packages\torch\utils\data\dataloader.py", line 1372, in _process_data
    data.reraise()
  File "D:\anaconda3\envs\pt\Lib\site-packages\torch\_utils.py", line 722, in reraise
    raise exception
NameError: Caught NameError in DataLoader worker process 0.
Original Traceback (most recent call last):
  File "D:\anaconda3\envs\pt\Lib\site-packages\torch\utils\data\_utils\worker.py", line 308, in _worker_loop
    data = fetcher.fetch(index)
           ^^^^^^^^^^^^^^^^^^^^
  File "D:\anaconda3\envs\pt\Lib\site-packages\torch\utils\data\_utils\fetch.py", line 54, in fetch
    return self.collate_fn(data)
           ^^^^^^^^^^^^^^^^^^^^^
  File "D:\Engineering\Fourth_Year\First_Term\Graduation\Graduation-Project\src\x_reporto\trainer\x_reporto_trainer.py", line 732, in collate_fn
    (object_detector_batch,selection_classifier_batch,abnormal_classifier_batch,LM_batch) = batch[k]
                                                                                                  ^
NameError: name 'k' is not defined

2024-02-23 14:52:15 - INFO - =================== New Run Started: 2024-02-23 14:52:15 ===================
2024-02-23 14:52:15 - INFO - Tarning X_Reporto Started
2024-02-23 14:52:15 - INFO - MODEL_STAGE: 3
2024-02-23 14:52:15 - INFO - DEVICE: cuda
2024-02-23 14:52:15 - INFO - CONTINUE_TRAIN: False
2024-02-23 14:52:15 - INFO - TRAIN_RPN: True
2024-02-23 14:52:15 - INFO - RUN: 0
2024-02-23 14:52:15 - INFO - EPOCHS: 5
2024-02-23 14:52:15 - INFO - BATCH_SIZE: 4
2024-02-23 14:52:15 - INFO - LM_Batch_Size: 1
2024-02-23 14:52:15 - INFO - LEARNING_RATE: 0.0001
2024-02-23 14:52:15 - INFO - SCHEDULAR_STEP_SIZE: 1500
2024-02-23 14:52:15 - INFO - SCHEDULAR_GAMMA: 0.9
2024-02-23 14:52:15 - INFO - DEBUG: True
2024-02-23 14:52:15 - INFO - GENERATE_REPORT: False
2024-02-23 14:52:15 - INFO - ABNORMAL_CLASSIFIER_POS_WEIGHT: 6.0
2024-02-23 14:52:15 - INFO - REGION_SELECTION_CLASSIFIER_POS_WEIGHT: 2.24
2024-02-23 14:52:15 - INFO - training_csv_path: datasets/train.csv
2024-02-23 14:52:15 - INFO - validation_csv_path: datasets/train.csv
2024-02-23 14:52:15 - INFO - PERIODIC_LOGGING: False
2024-02-23 14:52:15 - INFO - Folder 'models/0' already exists.
2024-02-23 14:52:18 - DEBUG - Starting new HTTPS connection (1): huggingface.co:443
2024-02-23 14:52:19 - DEBUG - https://huggingface.co:443 "HEAD /gpt2/resolve/main/config.json HTTP/1.1" 200 0
2024-02-23 14:52:19 - DEBUG - https://huggingface.co:443 "HEAD /gpt2/resolve/main/config.json HTTP/1.1" 200 0
2024-02-23 14:52:20 - DEBUG - https://huggingface.co:443 "HEAD /gpt2/resolve/main/generation_config.json HTTP/1.1" 200 0
2024-02-23 14:52:23 - DEBUG - https://huggingface.co:443 "HEAD /healx/gpt-2-pubmed-medium/resolve/main/tokenizer_config.json HTTP/1.1" 200 0
2024-02-23 14:52:42 - ERROR - An error occurred
Traceback (most recent call last):
  File "D:\Engineering\Fourth_Year\First_Term\Graduation\Graduation-Project\src\x_reporto\trainer\x_reporto_trainer.py", line 817, in <module>
    main()
  File "D:\Engineering\Fourth_Year\First_Term\Graduation\Graduation-Project\src\x_reporto\trainer\x_reporto_trainer.py", line 805, in main
    trainer.train()
  File "D:\Engineering\Fourth_Year\First_Term\Graduation\Graduation-Project\src\x_reporto\trainer\x_reporto_trainer.py", line 151, in train
    object_detector_losses,selection_classifier_losses,abnormal_binary_classifier_losses,LM_losses,stop= self.model(images,input_ids,attention_mask, object_detector_targets,selection_classifier_targets,abnormal_classifier_targets,LM_targets,batch,i)
                                                                                                         ^^^^^^^^^^^^^^^^^^^^^^^^^^^^^^^^^^^^^^^^^^^^^^^^^^^^^^^^^^^^^^^^^^^^^^^^^^^^^^^^^^^^^^^^^^^^^^^^^^^^^^^^^^^^^^^^^^^^^^^^^^^^^^^^^^^^^^^^^^^^^^^^
  File "D:\anaconda3\envs\pt\Lib\site-packages\torch\nn\modules\module.py", line 1511, in _wrapped_call_impl
    return self._call_impl(*args, **kwargs)
           ^^^^^^^^^^^^^^^^^^^^^^^^^^^^^^^^
  File "D:\anaconda3\envs\pt\Lib\site-packages\torch\nn\modules\module.py", line 1520, in _call_impl
    return forward_call(*args, **kwargs)
           ^^^^^^^^^^^^^^^^^^^^^^^^^^^^^
  File "D:\Engineering\Fourth_Year\First_Term\Graduation\Graduation-Project\src\x_reporto\models\x_reporto_v1.py", line 289, in forward
    object_detector_detected_classes=object_detector_detected_classes.to(DEVICE)
                                     ^^^^^^^^^^^^^^^^^^^^^^^^^^^^^^^^^^^
AttributeError: 'NoneType' object has no attribute 'to'
2024-02-23 14:56:24 - INFO - =================== New Run Started: 2024-02-23 14:56:24 ===================
2024-02-23 14:56:24 - INFO - Tarning X_Reporto Started
2024-02-23 14:56:24 - INFO - MODEL_STAGE: 3
2024-02-23 14:56:24 - INFO - DEVICE: cuda
2024-02-23 14:56:24 - INFO - CONTINUE_TRAIN: False
2024-02-23 14:56:24 - INFO - TRAIN_RPN: False
2024-02-23 14:56:24 - INFO - RUN: 0
2024-02-23 14:56:24 - INFO - EPOCHS: 5
2024-02-23 14:56:24 - INFO - BATCH_SIZE: 4
2024-02-23 14:56:24 - INFO - LM_Batch_Size: 1
2024-02-23 14:56:24 - INFO - LEARNING_RATE: 0.0001
2024-02-23 14:56:24 - INFO - SCHEDULAR_STEP_SIZE: 1500
2024-02-23 14:56:24 - INFO - SCHEDULAR_GAMMA: 0.9
2024-02-23 14:56:24 - INFO - DEBUG: True
2024-02-23 14:56:24 - INFO - GENERATE_REPORT: False
2024-02-23 14:56:24 - INFO - ABNORMAL_CLASSIFIER_POS_WEIGHT: 6.0
2024-02-23 14:56:24 - INFO - REGION_SELECTION_CLASSIFIER_POS_WEIGHT: 2.24
2024-02-23 14:56:24 - INFO - training_csv_path: datasets/train.csv
2024-02-23 14:56:24 - INFO - validation_csv_path: datasets/train.csv
2024-02-23 14:56:24 - INFO - PERIODIC_LOGGING: False
2024-02-23 14:56:24 - INFO - Folder 'models/0' already exists.
2024-02-23 14:56:27 - DEBUG - Starting new HTTPS connection (1): huggingface.co:443
2024-02-23 14:56:28 - DEBUG - https://huggingface.co:443 "HEAD /gpt2/resolve/main/config.json HTTP/1.1" 200 0
2024-02-23 14:56:28 - DEBUG - https://huggingface.co:443 "HEAD /gpt2/resolve/main/config.json HTTP/1.1" 200 0
2024-02-23 14:56:29 - DEBUG - https://huggingface.co:443 "HEAD /gpt2/resolve/main/generation_config.json HTTP/1.1" 200 0
2024-02-23 14:56:31 - DEBUG - https://huggingface.co:443 "HEAD /healx/gpt-2-pubmed-medium/resolve/main/tokenizer_config.json HTTP/1.1" 200 0
2024-02-23 14:56:47 - ERROR - An error occurred
Traceback (most recent call last):
  File "D:\Engineering\Fourth_Year\First_Term\Graduation\Graduation-Project\src\x_reporto\trainer\x_reporto_trainer.py", line 817, in <module>
    main()
  File "D:\Engineering\Fourth_Year\First_Term\Graduation\Graduation-Project\src\x_reporto\trainer\x_reporto_trainer.py", line 805, in main
    trainer.train()
  File "D:\Engineering\Fourth_Year\First_Term\Graduation\Graduation-Project\src\x_reporto\trainer\x_reporto_trainer.py", line 151, in train
    object_detector_losses,selection_classifier_losses,abnormal_binary_classifier_losses,LM_losses,stop= self.model(images,input_ids,attention_mask, object_detector_targets,selection_classifier_targets,abnormal_classifier_targets,LM_targets,batch,i)
                                                                                                         ^^^^^^^^^^^^^^^^^^^^^^^^^^^^^^^^^^^^^^^^^^^^^^^^^^^^^^^^^^^^^^^^^^^^^^^^^^^^^^^^^^^^^^^^^^^^^^^^^^^^^^^^^^^^^^^^^^^^^^^^^^^^^^^^^^^^^^^^^^^^^^^^
  File "D:\anaconda3\envs\pt\Lib\site-packages\torch\nn\modules\module.py", line 1511, in _wrapped_call_impl
    return self._call_impl(*args, **kwargs)
           ^^^^^^^^^^^^^^^^^^^^^^^^^^^^^^^^
  File "D:\anaconda3\envs\pt\Lib\site-packages\torch\nn\modules\module.py", line 1520, in _call_impl
    return forward_call(*args, **kwargs)
           ^^^^^^^^^^^^^^^^^^^^^^^^^^^^^
  File "D:\Engineering\Fourth_Year\First_Term\Graduation\Graduation-Project\src\x_reporto\models\x_reporto_v1.py", line 290, in forward
    selection_classifier_losses,_,_=self.binary_classifier_selection_region(object_detector_features,object_detector_detected_classes,selection_classifier_targets)
                                    ^^^^^^^^^^^^^^^^^^^^^^^^^^^^^^^^^^^^^^^^^^^^^^^^^^^^^^^^^^^^^^^^^^^^^^^^^^^^^^^^^^^^^^^^^^^^^^^^^^^^^^^^^^^^^^^^^^^^^^^^^^^^^^^
  File "D:\anaconda3\envs\pt\Lib\site-packages\torch\nn\modules\module.py", line 1511, in _wrapped_call_impl
    return self._call_impl(*args, **kwargs)
           ^^^^^^^^^^^^^^^^^^^^^^^^^^^^^^^^
  File "D:\anaconda3\envs\pt\Lib\site-packages\torch\nn\modules\module.py", line 1520, in _call_impl
    return forward_call(*args, **kwargs)
           ^^^^^^^^^^^^^^^^^^^^^^^^^^^^^
  File "D:\Engineering\Fourth_Year\First_Term\Graduation\Graduation-Project\src\binary_classifier\models\binary_classifier_selection_region_factory.py", line 60, in forward
    classifier_losses=self.selection_binary_classifier(object_detector_features,object_detector_detected_classes,selection_classifier_targets)
                      ^^^^^^^^^^^^^^^^^^^^^^^^^^^^^^^^^^^^^^^^^^^^^^^^^^^^^^^^^^^^^^^^^^^^^^^^^^^^^^^^^^^^^^^^^^^^^^^^^^^^^^^^^^^^^^^^^^^^^^^^
  File "D:\anaconda3\envs\pt\Lib\site-packages\torch\nn\modules\module.py", line 1511, in _wrapped_call_impl
    return self._call_impl(*args, **kwargs)
           ^^^^^^^^^^^^^^^^^^^^^^^^^^^^^^^^
  File "D:\anaconda3\envs\pt\Lib\site-packages\torch\nn\modules\module.py", line 1520, in _call_impl
    return forward_call(*args, **kwargs)
           ^^^^^^^^^^^^^^^^^^^^^^^^^^^^^
  File "D:\Engineering\Fourth_Year\First_Term\Graduation\Graduation-Project\src\binary_classifier\models\binary_classifier_selection_region_v1.py", line 71, in forward
    detected_region_has_sentence = region_has_sentence[class_detected]
                                   ~~~~~~~~~~~~~~~~~~~^^^^^^^^^^^^^^^^
IndexError: too many indices for tensor of dimension 1
2024-02-23 14:59:50 - INFO - =================== New Run Started: 2024-02-23 14:59:50 ===================
2024-02-23 14:59:50 - INFO - Tarning X_Reporto Started
2024-02-23 14:59:50 - INFO - MODEL_STAGE: 3
2024-02-23 14:59:50 - INFO - DEVICE: cuda
2024-02-23 14:59:50 - INFO - CONTINUE_TRAIN: False
2024-02-23 14:59:50 - INFO - TRAIN_RPN: False
2024-02-23 14:59:50 - INFO - RUN: 0
2024-02-23 14:59:50 - INFO - EPOCHS: 5
2024-02-23 14:59:50 - INFO - BATCH_SIZE: 4
2024-02-23 14:59:50 - INFO - LM_Batch_Size: 1
2024-02-23 14:59:50 - INFO - LEARNING_RATE: 0.0001
2024-02-23 14:59:50 - INFO - SCHEDULAR_STEP_SIZE: 1500
2024-02-23 14:59:50 - INFO - SCHEDULAR_GAMMA: 0.9
2024-02-23 14:59:50 - INFO - DEBUG: True
2024-02-23 14:59:50 - INFO - GENERATE_REPORT: False
2024-02-23 14:59:50 - INFO - ABNORMAL_CLASSIFIER_POS_WEIGHT: 6.0
2024-02-23 14:59:50 - INFO - REGION_SELECTION_CLASSIFIER_POS_WEIGHT: 2.24
2024-02-23 14:59:50 - INFO - training_csv_path: datasets/train.csv
2024-02-23 14:59:50 - INFO - validation_csv_path: datasets/train.csv
2024-02-23 14:59:50 - INFO - PERIODIC_LOGGING: False
2024-02-23 14:59:50 - INFO - Folder 'models/0' already exists.
2024-02-23 14:59:53 - DEBUG - Starting new HTTPS connection (1): huggingface.co:443
2024-02-23 14:59:54 - DEBUG - https://huggingface.co:443 "HEAD /gpt2/resolve/main/config.json HTTP/1.1" 200 0
2024-02-23 14:59:54 - DEBUG - https://huggingface.co:443 "HEAD /gpt2/resolve/main/config.json HTTP/1.1" 200 0
2024-02-23 14:59:55 - DEBUG - https://huggingface.co:443 "HEAD /gpt2/resolve/main/generation_config.json HTTP/1.1" 200 0
2024-02-23 14:59:58 - DEBUG - https://huggingface.co:443 "HEAD /healx/gpt-2-pubmed-medium/resolve/main/tokenizer_config.json HTTP/1.1" 200 0
